[2025-02-16T01:07:15.745+0000] {local_task_job_runner.py:123} INFO - ::group::Pre task execution logs
[2025-02-16T01:07:15.762+0000] {taskinstance.py:2614} INFO - Dependencies all met for dep_context=non-requeueable deps ti=<TaskInstance: dag_email_on_new_data.wait_for_status_file manual__2025-02-16T01:02:09.835791+00:00 [queued]>
[2025-02-16T01:07:15.770+0000] {taskinstance.py:2614} INFO - Dependencies all met for dep_context=requeueable deps ti=<TaskInstance: dag_email_on_new_data.wait_for_status_file manual__2025-02-16T01:02:09.835791+00:00 [queued]>
[2025-02-16T01:07:15.771+0000] {taskinstance.py:2867} INFO - Starting attempt 2 of 2
[2025-02-16T01:07:15.785+0000] {taskinstance.py:2890} INFO - Executing <Task(FileSensor): wait_for_status_file> on 2025-02-16 01:02:09.835791+00:00
[2025-02-16T01:07:15.795+0000] {logging_mixin.py:190} WARNING - /home/***/.local/lib/python3.12/site-packages/***/task/task_runner/standard_task_runner.py:70 DeprecationWarning: This process (pid=55769) is multi-threaded, use of fork() may lead to deadlocks in the child.
[2025-02-16T01:07:15.795+0000] {standard_task_runner.py:104} INFO - Running: ['***', 'tasks', 'run', 'dag_email_on_new_data', 'wait_for_status_file', 'manual__2025-02-16T01:02:09.835791+00:00', '--job-id', '131', '--raw', '--subdir', 'DAGS_FOLDER/dag_6.py', '--cfg-path', '/tmp/tmpmj70lck9']
[2025-02-16T01:07:15.796+0000] {standard_task_runner.py:72} INFO - Started process 55802 to run task
[2025-02-16T01:07:15.797+0000] {standard_task_runner.py:105} INFO - Job 131: Subtask wait_for_status_file
[2025-02-16T01:07:15.845+0000] {task_command.py:467} INFO - Running <TaskInstance: dag_email_on_new_data.wait_for_status_file manual__2025-02-16T01:02:09.835791+00:00 [running]> on host ce687c8aaad7
[2025-02-16T01:07:15.932+0000] {taskinstance.py:3134} INFO - Exporting env vars: AIRFLOW_CTX_DAG_EMAIL='nikshay.p.jain@gmail.com' AIRFLOW_CTX_DAG_OWNER='***' AIRFLOW_CTX_DAG_ID='dag_email_on_new_data' AIRFLOW_CTX_TASK_ID='wait_for_status_file' AIRFLOW_CTX_EXECUTION_DATE='2025-02-16T01:02:09.835791+00:00' AIRFLOW_CTX_TRY_NUMBER='2' AIRFLOW_CTX_DAG_RUN_ID='manual__2025-02-16T01:02:09.835791+00:00'
[2025-02-16T01:07:15.933+0000] {logging_mixin.py:190} INFO - Task instance is in running state
[2025-02-16T01:07:15.934+0000] {logging_mixin.py:190} INFO -  Previous state of the Task instance: queued
[2025-02-16T01:07:15.935+0000] {logging_mixin.py:190} INFO - Current task name:wait_for_status_file state:running start_date:2025-02-16 01:07:15.762786+00:00
[2025-02-16T01:07:15.936+0000] {logging_mixin.py:190} INFO - Dag name:dag_email_on_new_data and current dag run status:running
[2025-02-16T01:07:15.936+0000] {taskinstance.py:732} INFO - ::endgroup::
[2025-02-16T01:07:15.937+0000] {baseoperator.py:423} WARNING - FileSensor.execute cannot be called outside TaskInstance!
[2025-02-16T01:07:15.954+0000] {taskinstance.py:3313} ERROR - Task failed with exception
Traceback (most recent call last):
  File "/home/airflow/.local/lib/python3.12/site-packages/airflow/models/taskinstance.py", line 768, in _execute_task
    result = _execute_callable(context=context, **execute_callable_kwargs)
             ^^^^^^^^^^^^^^^^^^^^^^^^^^^^^^^^^^^^^^^^^^^^^^^^^^^^^^^^^^^^^
  File "/home/airflow/.local/lib/python3.12/site-packages/airflow/models/taskinstance.py", line 734, in _execute_callable
    return ExecutionCallableRunner(
           ^^^^^^^^^^^^^^^^^^^^^^^^
  File "/home/airflow/.local/lib/python3.12/site-packages/airflow/utils/operator_helpers.py", line 252, in run
    return self.func(*args, **kwargs)
           ^^^^^^^^^^^^^^^^^^^^^^^^^^
  File "/home/airflow/.local/lib/python3.12/site-packages/airflow/models/baseoperator.py", line 424, in wrapper
    return func(self, *args, **kwargs)
           ^^^^^^^^^^^^^^^^^^^^^^^^^^^
  File "/home/airflow/.local/lib/python3.12/site-packages/airflow/sensors/filesystem.py", line 123, in execute
    super().execute(context=context)
  File "/home/airflow/.local/lib/python3.12/site-packages/airflow/models/baseoperator.py", line 424, in wrapper
    return func(self, *args, **kwargs)
           ^^^^^^^^^^^^^^^^^^^^^^^^^^^
  File "/home/airflow/.local/lib/python3.12/site-packages/airflow/sensors/base.py", line 309, in execute
    raise e
  File "/home/airflow/.local/lib/python3.12/site-packages/airflow/sensors/base.py", line 289, in execute
    poke_return = self.poke(context)
                  ^^^^^^^^^^^^^^^^^^
  File "/home/airflow/.local/lib/python3.12/site-packages/airflow/sensors/filesystem.py", line 109, in poke
    self.log.info("Poking for file %s", self.path)
                                        ^^^^^^^^^
  File "/usr/local/lib/python3.12/functools.py", line 998, in __get__
    val = self.func(instance)
          ^^^^^^^^^^^^^^^^^^^
  File "/home/airflow/.local/lib/python3.12/site-packages/airflow/sensors/filesystem.py", line 103, in path
    hook = FSHook(self.fs_conn_id)
           ^^^^^^^^^^^^^^^^^^^^^^^
  File "/home/airflow/.local/lib/python3.12/site-packages/airflow/hooks/filesystem.py", line 64, in __init__
    conn = self.get_connection(fs_conn_id)
           ^^^^^^^^^^^^^^^^^^^^^^^^^^^^^^^
  File "/home/airflow/.local/lib/python3.12/site-packages/airflow/hooks/base.py", line 83, in get_connection
    conn = Connection.get_connection_from_secrets(conn_id)
           ^^^^^^^^^^^^^^^^^^^^^^^^^^^^^^^^^^^^^^^^^^^^^^^
  File "/home/airflow/.local/lib/python3.12/site-packages/airflow/models/connection.py", line 537, in get_connection_from_secrets
    raise AirflowNotFoundException(f"The conn_id `{conn_id}` isn't defined")
airflow.exceptions.AirflowNotFoundException: The conn_id `fs_default` isn't defined
[2025-02-16T01:07:15.965+0000] {logging_mixin.py:190} INFO - Task instance in failure state
[2025-02-16T01:07:15.965+0000] {logging_mixin.py:190} INFO - Task start:2025-02-16 01:07:15.762786+00:00 end:2025-02-16 01:07:15.964770+00:00 duration:0.201984
[2025-02-16T01:07:15.966+0000] {logging_mixin.py:190} INFO - Task:<Task(FileSensor): wait_for_status_file> dag:<DAG: dag_email_on_new_data> dagrun:<DagRun dag_email_on_new_data @ 2025-02-16 01:02:09.835791+00:00: manual__2025-02-16T01:02:09.835791+00:00, state:running, queued_at: 2025-02-16 01:02:09.962079+00:00. externally triggered: True>
[2025-02-16T01:07:15.967+0000] {logging_mixin.py:190} INFO - Failure caused by The conn_id `fs_default` isn't defined
[2025-02-16T01:07:15.967+0000] {taskinstance.py:1226} INFO - Marking task as FAILED. dag_id=dag_email_on_new_data, task_id=wait_for_status_file, run_id=manual__2025-02-16T01:02:09.835791+00:00, execution_date=20250216T010209, start_date=20250216T010715, end_date=20250216T010715
[2025-02-16T01:07:15.995+0000] {taskinstance.py:341} INFO - ::group::Post task execution logs
[2025-02-16T01:07:15.995+0000] {standard_task_runner.py:124} ERROR - Failed to execute job 131 for task wait_for_status_file (The conn_id `fs_default` isn't defined; 55802)
Traceback (most recent call last):
  File "/home/airflow/.local/lib/python3.12/site-packages/airflow/task/task_runner/standard_task_runner.py", line 117, in _start_by_fork
    ret = args.func(args, dag=self.dag)
          ^^^^^^^^^^^^^^^^^^^^^^^^^^^^^
  File "/home/airflow/.local/lib/python3.12/site-packages/airflow/cli/cli_config.py", line 49, in command
    return func(*args, **kwargs)
           ^^^^^^^^^^^^^^^^^^^^^
  File "/home/airflow/.local/lib/python3.12/site-packages/airflow/utils/cli.py", line 116, in wrapper
    return f(*args, **kwargs)
           ^^^^^^^^^^^^^^^^^^
  File "/home/airflow/.local/lib/python3.12/site-packages/airflow/cli/commands/task_command.py", line 483, in task_run
    task_return_code = _run_task_by_selected_method(args, _dag, ti)
                       ^^^^^^^^^^^^^^^^^^^^^^^^^^^^^^^^^^^^^^^^^^^^
  File "/home/airflow/.local/lib/python3.12/site-packages/airflow/cli/commands/task_command.py", line 256, in _run_task_by_selected_method
    return _run_raw_task(args, ti)
           ^^^^^^^^^^^^^^^^^^^^^^^
  File "/home/airflow/.local/lib/python3.12/site-packages/airflow/cli/commands/task_command.py", line 341, in _run_raw_task
    return ti._run_raw_task(
           ^^^^^^^^^^^^^^^^^
  File "/home/airflow/.local/lib/python3.12/site-packages/airflow/utils/session.py", line 97, in wrapper
    return func(*args, session=session, **kwargs)
           ^^^^^^^^^^^^^^^^^^^^^^^^^^^^^^^^^^^^^^
  File "/home/airflow/.local/lib/python3.12/site-packages/airflow/models/taskinstance.py", line 3006, in _run_raw_task
    return _run_raw_task(
           ^^^^^^^^^^^^^^
  File "/home/airflow/.local/lib/python3.12/site-packages/airflow/models/taskinstance.py", line 274, in _run_raw_task
    TaskInstance._execute_task_with_callbacks(
  File "/home/airflow/.local/lib/python3.12/site-packages/airflow/models/taskinstance.py", line 3161, in _execute_task_with_callbacks
    result = self._execute_task(context, task_orig)
             ^^^^^^^^^^^^^^^^^^^^^^^^^^^^^^^^^^^^^^
  File "/home/airflow/.local/lib/python3.12/site-packages/airflow/models/taskinstance.py", line 3185, in _execute_task
    return _execute_task(self, context, task_orig)
           ^^^^^^^^^^^^^^^^^^^^^^^^^^^^^^^^^^^^^^^
  File "/home/airflow/.local/lib/python3.12/site-packages/airflow/models/taskinstance.py", line 768, in _execute_task
    result = _execute_callable(context=context, **execute_callable_kwargs)
             ^^^^^^^^^^^^^^^^^^^^^^^^^^^^^^^^^^^^^^^^^^^^^^^^^^^^^^^^^^^^^
  File "/home/airflow/.local/lib/python3.12/site-packages/airflow/models/taskinstance.py", line 734, in _execute_callable
    return ExecutionCallableRunner(
           ^^^^^^^^^^^^^^^^^^^^^^^^
  File "/home/airflow/.local/lib/python3.12/site-packages/airflow/utils/operator_helpers.py", line 252, in run
    return self.func(*args, **kwargs)
           ^^^^^^^^^^^^^^^^^^^^^^^^^^
  File "/home/airflow/.local/lib/python3.12/site-packages/airflow/models/baseoperator.py", line 424, in wrapper
    return func(self, *args, **kwargs)
           ^^^^^^^^^^^^^^^^^^^^^^^^^^^
  File "/home/airflow/.local/lib/python3.12/site-packages/airflow/sensors/filesystem.py", line 123, in execute
    super().execute(context=context)
  File "/home/airflow/.local/lib/python3.12/site-packages/airflow/models/baseoperator.py", line 424, in wrapper
    return func(self, *args, **kwargs)
           ^^^^^^^^^^^^^^^^^^^^^^^^^^^
  File "/home/airflow/.local/lib/python3.12/site-packages/airflow/sensors/base.py", line 309, in execute
    raise e
  File "/home/airflow/.local/lib/python3.12/site-packages/airflow/sensors/base.py", line 289, in execute
    poke_return = self.poke(context)
                  ^^^^^^^^^^^^^^^^^^
  File "/home/airflow/.local/lib/python3.12/site-packages/airflow/sensors/filesystem.py", line 109, in poke
    self.log.info("Poking for file %s", self.path)
                                        ^^^^^^^^^
  File "/usr/local/lib/python3.12/functools.py", line 998, in __get__
    val = self.func(instance)
          ^^^^^^^^^^^^^^^^^^^
  File "/home/airflow/.local/lib/python3.12/site-packages/airflow/sensors/filesystem.py", line 103, in path
    hook = FSHook(self.fs_conn_id)
           ^^^^^^^^^^^^^^^^^^^^^^^
  File "/home/airflow/.local/lib/python3.12/site-packages/airflow/hooks/filesystem.py", line 64, in __init__
    conn = self.get_connection(fs_conn_id)
           ^^^^^^^^^^^^^^^^^^^^^^^^^^^^^^^
  File "/home/airflow/.local/lib/python3.12/site-packages/airflow/hooks/base.py", line 83, in get_connection
    conn = Connection.get_connection_from_secrets(conn_id)
           ^^^^^^^^^^^^^^^^^^^^^^^^^^^^^^^^^^^^^^^^^^^^^^^
  File "/home/airflow/.local/lib/python3.12/site-packages/airflow/models/connection.py", line 537, in get_connection_from_secrets
    raise AirflowNotFoundException(f"The conn_id `{conn_id}` isn't defined")
airflow.exceptions.AirflowNotFoundException: The conn_id `fs_default` isn't defined
[2025-02-16T01:07:16.013+0000] {local_task_job_runner.py:266} INFO - Task exited with return code 1
[2025-02-16T01:07:16.042+0000] {taskinstance.py:3901} INFO - 0 downstream tasks scheduled from follow-on schedule check
[2025-02-16T01:07:16.048+0000] {local_task_job_runner.py:245} INFO - ::endgroup::
