[2025-02-15T19:46:23.300+0000] {local_task_job_runner.py:123} INFO - ::group::Pre task execution logs
[2025-02-15T19:46:23.331+0000] {taskinstance.py:2614} INFO - Dependencies all met for dep_context=non-requeueable deps ti=<TaskInstance: dag_mod1.main1 manual__2025-02-15T19:41:17.170958+00:00 [queued]>
[2025-02-15T19:46:23.351+0000] {taskinstance.py:2614} INFO - Dependencies all met for dep_context=requeueable deps ti=<TaskInstance: dag_mod1.main1 manual__2025-02-15T19:41:17.170958+00:00 [queued]>
[2025-02-15T19:46:23.353+0000] {taskinstance.py:2867} INFO - Starting attempt 2 of 6
[2025-02-15T19:46:23.387+0000] {taskinstance.py:2890} INFO - Executing <Task(PythonOperator): main1> on 2025-02-15 19:41:17.170958+00:00
[2025-02-15T19:46:23.422+0000] {standard_task_runner.py:104} INFO - Running: ['***', 'tasks', 'run', 'dag_mod1', 'main1', 'manual__2025-02-15T19:41:17.170958+00:00', '--job-id', '33', '--raw', '--subdir', 'DAGS_FOLDER/dag_mod1.py', '--cfg-path', '/tmp/tmp4ec7kk9e']
[2025-02-15T19:46:23.425+0000] {standard_task_runner.py:105} INFO - Job 33: Subtask main1
[2025-02-15T19:46:23.430+0000] {logging_mixin.py:190} WARNING - /home/***/.local/lib/python3.12/site-packages/***/task/task_runner/standard_task_runner.py:70 DeprecationWarning: This process (pid=10390) is multi-threaded, use of fork() may lead to deadlocks in the child.
[2025-02-15T19:46:23.435+0000] {standard_task_runner.py:72} INFO - Started process 10428 to run task
[2025-02-15T19:46:23.782+0000] {task_command.py:467} INFO - Running <TaskInstance: dag_mod1.main1 manual__2025-02-15T19:41:17.170958+00:00 [running]> on host 44ff243c60ac
[2025-02-15T19:46:24.025+0000] {taskinstance.py:3134} INFO - Exporting env vars: AIRFLOW_CTX_DAG_OWNER='***' AIRFLOW_CTX_DAG_ID='dag_mod1' AIRFLOW_CTX_TASK_ID='main1' AIRFLOW_CTX_EXECUTION_DATE='2025-02-15T19:41:17.170958+00:00' AIRFLOW_CTX_TRY_NUMBER='2' AIRFLOW_CTX_DAG_RUN_ID='manual__2025-02-15T19:41:17.170958+00:00'
[2025-02-15T19:46:24.028+0000] {logging_mixin.py:190} INFO - Task instance is in running state
[2025-02-15T19:46:24.029+0000] {logging_mixin.py:190} INFO -  Previous state of the Task instance: queued
[2025-02-15T19:46:24.029+0000] {logging_mixin.py:190} INFO - Current task name:main1 state:running start_date:2025-02-15 19:46:23.332190+00:00
[2025-02-15T19:46:24.030+0000] {logging_mixin.py:190} INFO - Dag name:dag_mod1 and current dag run status:running
[2025-02-15T19:46:24.031+0000] {taskinstance.py:732} INFO - ::endgroup::
[2025-02-15T19:46:24.360+0000] {taskinstance.py:3313} ERROR - Task failed with exception
Traceback (most recent call last):
  File "/home/airflow/.local/lib/python3.12/site-packages/airflow/models/taskinstance.py", line 768, in _execute_task
    result = _execute_callable(context=context, **execute_callable_kwargs)
             ^^^^^^^^^^^^^^^^^^^^^^^^^^^^^^^^^^^^^^^^^^^^^^^^^^^^^^^^^^^^^
  File "/home/airflow/.local/lib/python3.12/site-packages/airflow/models/taskinstance.py", line 734, in _execute_callable
    return ExecutionCallableRunner(
           ^^^^^^^^^^^^^^^^^^^^^^^^
  File "/home/airflow/.local/lib/python3.12/site-packages/airflow/utils/operator_helpers.py", line 252, in run
    return self.func(*args, **kwargs)
           ^^^^^^^^^^^^^^^^^^^^^^^^^^
  File "/home/airflow/.local/lib/python3.12/site-packages/airflow/models/baseoperator.py", line 424, in wrapper
    return func(self, *args, **kwargs)
           ^^^^^^^^^^^^^^^^^^^^^^^^^^^
  File "/home/airflow/.local/lib/python3.12/site-packages/airflow/operators/python.py", line 238, in execute
    return_value = self.execute_callable()
                   ^^^^^^^^^^^^^^^^^^^^^^^
  File "/home/airflow/.local/lib/python3.12/site-packages/airflow/operators/python.py", line 256, in execute_callable
    return runner.run(*self.op_args, **self.op_kwargs)
           ^^^^^^^^^^^^^^^^^^^^^^^^^^^^^^^^^^^^^^^^^^^
  File "/home/airflow/.local/lib/python3.12/site-packages/airflow/utils/operator_helpers.py", line 252, in run
    return self.func(*args, **kwargs)
           ^^^^^^^^^^^^^^^^^^^^^^^^^^
  File "/opt/airflow/assign2/main1.py", line 22, in main1
    driver = webdriver.Firefox(options=options)
             ^^^^^^^^^^^^^^^^^^^^^^^^^^^^^^^^^^
  File "/home/airflow/.local/lib/python3.12/site-packages/selenium/webdriver/firefox/webdriver.py", line 71, in __init__
    super().__init__(command_executor=executor, options=options)
  File "/home/airflow/.local/lib/python3.12/site-packages/selenium/webdriver/remote/webdriver.py", line 250, in __init__
    self.start_session(capabilities)
  File "/home/airflow/.local/lib/python3.12/site-packages/selenium/webdriver/remote/webdriver.py", line 342, in start_session
    response = self.execute(Command.NEW_SESSION, caps)["value"]
               ^^^^^^^^^^^^^^^^^^^^^^^^^^^^^^^^^^^^^^^
  File "/home/airflow/.local/lib/python3.12/site-packages/selenium/webdriver/remote/webdriver.py", line 429, in execute
    self.error_handler.check_response(response)
  File "/home/airflow/.local/lib/python3.12/site-packages/selenium/webdriver/remote/errorhandler.py", line 232, in check_response
    raise exception_class(message, screen, stacktrace)
selenium.common.exceptions.WebDriverException: Message: Process unexpectedly closed with status 255

[2025-02-15T19:46:24.393+0000] {logging_mixin.py:190} INFO - Task instance in failure state
[2025-02-15T19:46:24.394+0000] {logging_mixin.py:190} INFO - Task start:2025-02-15 19:46:23.332190+00:00 end:2025-02-15 19:46:24.392196+00:00 duration:1.060006
[2025-02-15T19:46:24.396+0000] {logging_mixin.py:190} INFO - Task:<Task(PythonOperator): main1> dag:<DAG: dag_mod1> dagrun:<DagRun dag_mod1 @ 2025-02-15 19:41:17.170958+00:00: manual__2025-02-15T19:41:17.170958+00:00, state:running, queued_at: 2025-02-15 19:41:17.246047+00:00. externally triggered: True>
[2025-02-15T19:46:24.397+0000] {logging_mixin.py:190} INFO - Failure caused by Message: Process unexpectedly closed with status 255
[2025-02-15T19:46:24.398+0000] {taskinstance.py:1226} INFO - Marking task as UP_FOR_RETRY. dag_id=dag_mod1, task_id=main1, run_id=manual__2025-02-15T19:41:17.170958+00:00, execution_date=20250215T194117, start_date=20250215T194623, end_date=20250215T194624
[2025-02-15T19:46:24.464+0000] {taskinstance.py:341} INFO - ::group::Post task execution logs
[2025-02-15T19:46:24.465+0000] {standard_task_runner.py:124} ERROR - Failed to execute job 33 for task main1 (Message: Process unexpectedly closed with status 255
; 10428)
Traceback (most recent call last):
  File "/home/airflow/.local/lib/python3.12/site-packages/airflow/task/task_runner/standard_task_runner.py", line 117, in _start_by_fork
    ret = args.func(args, dag=self.dag)
          ^^^^^^^^^^^^^^^^^^^^^^^^^^^^^
  File "/home/airflow/.local/lib/python3.12/site-packages/airflow/cli/cli_config.py", line 49, in command
    return func(*args, **kwargs)
           ^^^^^^^^^^^^^^^^^^^^^
  File "/home/airflow/.local/lib/python3.12/site-packages/airflow/utils/cli.py", line 116, in wrapper
    return f(*args, **kwargs)
           ^^^^^^^^^^^^^^^^^^
  File "/home/airflow/.local/lib/python3.12/site-packages/airflow/cli/commands/task_command.py", line 483, in task_run
    task_return_code = _run_task_by_selected_method(args, _dag, ti)
                       ^^^^^^^^^^^^^^^^^^^^^^^^^^^^^^^^^^^^^^^^^^^^
  File "/home/airflow/.local/lib/python3.12/site-packages/airflow/cli/commands/task_command.py", line 256, in _run_task_by_selected_method
    return _run_raw_task(args, ti)
           ^^^^^^^^^^^^^^^^^^^^^^^
  File "/home/airflow/.local/lib/python3.12/site-packages/airflow/cli/commands/task_command.py", line 341, in _run_raw_task
    return ti._run_raw_task(
           ^^^^^^^^^^^^^^^^^
  File "/home/airflow/.local/lib/python3.12/site-packages/airflow/utils/session.py", line 97, in wrapper
    return func(*args, session=session, **kwargs)
           ^^^^^^^^^^^^^^^^^^^^^^^^^^^^^^^^^^^^^^
  File "/home/airflow/.local/lib/python3.12/site-packages/airflow/models/taskinstance.py", line 3006, in _run_raw_task
    return _run_raw_task(
           ^^^^^^^^^^^^^^
  File "/home/airflow/.local/lib/python3.12/site-packages/airflow/models/taskinstance.py", line 274, in _run_raw_task
    TaskInstance._execute_task_with_callbacks(
  File "/home/airflow/.local/lib/python3.12/site-packages/airflow/models/taskinstance.py", line 3161, in _execute_task_with_callbacks
    result = self._execute_task(context, task_orig)
             ^^^^^^^^^^^^^^^^^^^^^^^^^^^^^^^^^^^^^^
  File "/home/airflow/.local/lib/python3.12/site-packages/airflow/models/taskinstance.py", line 3185, in _execute_task
    return _execute_task(self, context, task_orig)
           ^^^^^^^^^^^^^^^^^^^^^^^^^^^^^^^^^^^^^^^
  File "/home/airflow/.local/lib/python3.12/site-packages/airflow/models/taskinstance.py", line 768, in _execute_task
    result = _execute_callable(context=context, **execute_callable_kwargs)
             ^^^^^^^^^^^^^^^^^^^^^^^^^^^^^^^^^^^^^^^^^^^^^^^^^^^^^^^^^^^^^
  File "/home/airflow/.local/lib/python3.12/site-packages/airflow/models/taskinstance.py", line 734, in _execute_callable
    return ExecutionCallableRunner(
           ^^^^^^^^^^^^^^^^^^^^^^^^
  File "/home/airflow/.local/lib/python3.12/site-packages/airflow/utils/operator_helpers.py", line 252, in run
    return self.func(*args, **kwargs)
           ^^^^^^^^^^^^^^^^^^^^^^^^^^
  File "/home/airflow/.local/lib/python3.12/site-packages/airflow/models/baseoperator.py", line 424, in wrapper
    return func(self, *args, **kwargs)
           ^^^^^^^^^^^^^^^^^^^^^^^^^^^
  File "/home/airflow/.local/lib/python3.12/site-packages/airflow/operators/python.py", line 238, in execute
    return_value = self.execute_callable()
                   ^^^^^^^^^^^^^^^^^^^^^^^
  File "/home/airflow/.local/lib/python3.12/site-packages/airflow/operators/python.py", line 256, in execute_callable
    return runner.run(*self.op_args, **self.op_kwargs)
           ^^^^^^^^^^^^^^^^^^^^^^^^^^^^^^^^^^^^^^^^^^^
  File "/home/airflow/.local/lib/python3.12/site-packages/airflow/utils/operator_helpers.py", line 252, in run
    return self.func(*args, **kwargs)
           ^^^^^^^^^^^^^^^^^^^^^^^^^^
  File "/opt/airflow/assign2/main1.py", line 22, in main1
    driver = webdriver.Firefox(options=options)
             ^^^^^^^^^^^^^^^^^^^^^^^^^^^^^^^^^^
  File "/home/airflow/.local/lib/python3.12/site-packages/selenium/webdriver/firefox/webdriver.py", line 71, in __init__
    super().__init__(command_executor=executor, options=options)
  File "/home/airflow/.local/lib/python3.12/site-packages/selenium/webdriver/remote/webdriver.py", line 250, in __init__
    self.start_session(capabilities)
  File "/home/airflow/.local/lib/python3.12/site-packages/selenium/webdriver/remote/webdriver.py", line 342, in start_session
    response = self.execute(Command.NEW_SESSION, caps)["value"]
               ^^^^^^^^^^^^^^^^^^^^^^^^^^^^^^^^^^^^^^^
  File "/home/airflow/.local/lib/python3.12/site-packages/selenium/webdriver/remote/webdriver.py", line 429, in execute
    self.error_handler.check_response(response)
  File "/home/airflow/.local/lib/python3.12/site-packages/selenium/webdriver/remote/errorhandler.py", line 232, in check_response
    raise exception_class(message, screen, stacktrace)
selenium.common.exceptions.WebDriverException: Message: Process unexpectedly closed with status 255

[2025-02-15T19:46:24.527+0000] {local_task_job_runner.py:266} INFO - Task exited with return code 1
[2025-02-15T19:46:24.558+0000] {taskinstance.py:3901} INFO - 0 downstream tasks scheduled from follow-on schedule check
[2025-02-15T19:46:24.561+0000] {local_task_job_runner.py:245} INFO - ::endgroup::
