[2025-02-16T00:06:14.815+0000] {local_task_job_runner.py:123} INFO - ::group::Pre task execution logs
[2025-02-16T00:06:14.840+0000] {taskinstance.py:2614} INFO - Dependencies all met for dep_context=non-requeueable deps ti=<TaskInstance: dag_mod1234.main4 scheduled__2025-02-15T00:00:00+00:00 [queued]>
[2025-02-16T00:06:14.852+0000] {taskinstance.py:2614} INFO - Dependencies all met for dep_context=requeueable deps ti=<TaskInstance: dag_mod1234.main4 scheduled__2025-02-15T00:00:00+00:00 [queued]>
[2025-02-16T00:06:14.877+0000] {taskinstance.py:2867} INFO - Starting attempt 2 of 6
[2025-02-16T00:06:15.055+0000] {taskinstance.py:2890} INFO - Executing <Task(PythonOperator): main4> on 2025-02-15 00:00:00+00:00
[2025-02-16T00:06:15.165+0000] {standard_task_runner.py:104} INFO - Running: ['***', 'tasks', 'run', 'dag_mod1234', 'main4', 'scheduled__2025-02-15T00:00:00+00:00', '--job-id', '111', '--raw', '--subdir', 'DAGS_FOLDER/dag_mod1.py', '--cfg-path', '/tmp/tmpvq7b_mph']
[2025-02-16T00:06:15.167+0000] {standard_task_runner.py:105} INFO - Job 111: Subtask main4
[2025-02-16T00:06:15.170+0000] {logging_mixin.py:190} WARNING - /home/***/.local/lib/python3.12/site-packages/***/task/task_runner/standard_task_runner.py:70 DeprecationWarning: This process (pid=19270) is multi-threaded, use of fork() may lead to deadlocks in the child.
[2025-02-16T00:06:15.171+0000] {standard_task_runner.py:72} INFO - Started process 19281 to run task
[2025-02-16T00:06:15.336+0000] {task_command.py:467} INFO - Running <TaskInstance: dag_mod1234.main4 scheduled__2025-02-15T00:00:00+00:00 [running]> on host ce687c8aaad7
[2025-02-16T00:06:15.929+0000] {taskinstance.py:3134} INFO - Exporting env vars: AIRFLOW_CTX_DAG_OWNER='***' AIRFLOW_CTX_DAG_ID='dag_mod1234' AIRFLOW_CTX_TASK_ID='main4' AIRFLOW_CTX_EXECUTION_DATE='2025-02-15T00:00:00+00:00' AIRFLOW_CTX_TRY_NUMBER='2' AIRFLOW_CTX_DAG_RUN_ID='scheduled__2025-02-15T00:00:00+00:00'
[2025-02-16T00:06:15.931+0000] {logging_mixin.py:190} INFO - Task instance is in running state
[2025-02-16T00:06:15.932+0000] {logging_mixin.py:190} INFO -  Previous state of the Task instance: queued
[2025-02-16T00:06:15.932+0000] {logging_mixin.py:190} INFO - Current task name:main4 state:running start_date:2025-02-16 00:06:14.841349+00:00
[2025-02-16T00:06:15.933+0000] {logging_mixin.py:190} INFO - Dag name:dag_mod1234 and current dag run status:running
[2025-02-16T00:06:15.933+0000] {taskinstance.py:732} INFO - ::endgroup::
[2025-02-16T00:06:15.937+0000] {logging_mixin.py:190} INFO - CSV file path: /opt/***/assign2/data_home.csv
[2025-02-16T00:06:16.487+0000] {logging_mixin.py:190} INFO - Columns in CSV: ['Headline', 'Image Path', 'Encoding']
[2025-02-16T00:06:16.500+0000] {base.py:84} INFO - Retrieving connection 'postgres_default'
[2025-02-16T00:06:18.326+0000] {taskinstance.py:3313} ERROR - Task failed with exception
Traceback (most recent call last):
  File "/home/airflow/.local/lib/python3.12/site-packages/airflow/models/taskinstance.py", line 768, in _execute_task
    result = _execute_callable(context=context, **execute_callable_kwargs)
             ^^^^^^^^^^^^^^^^^^^^^^^^^^^^^^^^^^^^^^^^^^^^^^^^^^^^^^^^^^^^^
  File "/home/airflow/.local/lib/python3.12/site-packages/airflow/models/taskinstance.py", line 734, in _execute_callable
    return ExecutionCallableRunner(
           ^^^^^^^^^^^^^^^^^^^^^^^^
  File "/home/airflow/.local/lib/python3.12/site-packages/airflow/utils/operator_helpers.py", line 252, in run
    return self.func(*args, **kwargs)
           ^^^^^^^^^^^^^^^^^^^^^^^^^^
  File "/home/airflow/.local/lib/python3.12/site-packages/airflow/models/baseoperator.py", line 424, in wrapper
    return func(self, *args, **kwargs)
           ^^^^^^^^^^^^^^^^^^^^^^^^^^^
  File "/home/airflow/.local/lib/python3.12/site-packages/airflow/operators/python.py", line 238, in execute
    return_value = self.execute_callable()
                   ^^^^^^^^^^^^^^^^^^^^^^^
  File "/home/airflow/.local/lib/python3.12/site-packages/airflow/operators/python.py", line 256, in execute_callable
    return runner.run(*self.op_args, **self.op_kwargs)
           ^^^^^^^^^^^^^^^^^^^^^^^^^^^^^^^^^^^^^^^^^^^
  File "/home/airflow/.local/lib/python3.12/site-packages/airflow/utils/operator_helpers.py", line 252, in run
    return self.func(*args, **kwargs)
           ^^^^^^^^^^^^^^^^^^^^^^^^^^
  File "/opt/airflow/assign2/main4.py", line 113, in main4
    with open('/opt/airflow/dags/run/status', 'w') as f:
         ^^^^^^^^^^^^^^^^^^^^^^^^^^^^^^^^^^^^^^^^^
FileNotFoundError: [Errno 2] No such file or directory: '/opt/airflow/dags/run/status'
[2025-02-16T00:06:18.350+0000] {logging_mixin.py:190} INFO - Task instance in failure state
[2025-02-16T00:06:18.351+0000] {logging_mixin.py:190} INFO - Task start:2025-02-16 00:06:14.841349+00:00 end:2025-02-16 00:06:18.350056+00:00 duration:3.508707
[2025-02-16T00:06:18.352+0000] {logging_mixin.py:190} INFO - Task:<Task(PythonOperator): main4> dag:<DAG: dag_mod1234> dagrun:<DagRun dag_mod1234 @ 2025-02-15 00:00:00+00:00: scheduled__2025-02-15T00:00:00+00:00, state:running, queued_at: 2025-02-16 00:00:00.486571+00:00. externally triggered: False>
[2025-02-16T00:06:18.353+0000] {logging_mixin.py:190} INFO - Failure caused by [Errno 2] No such file or directory: '/opt/***/dags/run/status'
[2025-02-16T00:06:18.353+0000] {taskinstance.py:1226} INFO - Marking task as UP_FOR_RETRY. dag_id=dag_mod1234, task_id=main4, run_id=scheduled__2025-02-15T00:00:00+00:00, execution_date=20250215T000000, start_date=20250216T000614, end_date=20250216T000618
[2025-02-16T00:06:18.407+0000] {taskinstance.py:341} INFO - ::group::Post task execution logs
[2025-02-16T00:06:18.408+0000] {standard_task_runner.py:124} ERROR - Failed to execute job 111 for task main4 ([Errno 2] No such file or directory: '/opt/airflow/dags/run/status'; 19281)
Traceback (most recent call last):
  File "/home/airflow/.local/lib/python3.12/site-packages/airflow/task/task_runner/standard_task_runner.py", line 117, in _start_by_fork
    ret = args.func(args, dag=self.dag)
          ^^^^^^^^^^^^^^^^^^^^^^^^^^^^^
  File "/home/airflow/.local/lib/python3.12/site-packages/airflow/cli/cli_config.py", line 49, in command
    return func(*args, **kwargs)
           ^^^^^^^^^^^^^^^^^^^^^
  File "/home/airflow/.local/lib/python3.12/site-packages/airflow/utils/cli.py", line 116, in wrapper
    return f(*args, **kwargs)
           ^^^^^^^^^^^^^^^^^^
  File "/home/airflow/.local/lib/python3.12/site-packages/airflow/cli/commands/task_command.py", line 483, in task_run
    task_return_code = _run_task_by_selected_method(args, _dag, ti)
                       ^^^^^^^^^^^^^^^^^^^^^^^^^^^^^^^^^^^^^^^^^^^^
  File "/home/airflow/.local/lib/python3.12/site-packages/airflow/cli/commands/task_command.py", line 256, in _run_task_by_selected_method
    return _run_raw_task(args, ti)
           ^^^^^^^^^^^^^^^^^^^^^^^
  File "/home/airflow/.local/lib/python3.12/site-packages/airflow/cli/commands/task_command.py", line 341, in _run_raw_task
    return ti._run_raw_task(
           ^^^^^^^^^^^^^^^^^
  File "/home/airflow/.local/lib/python3.12/site-packages/airflow/utils/session.py", line 97, in wrapper
    return func(*args, session=session, **kwargs)
           ^^^^^^^^^^^^^^^^^^^^^^^^^^^^^^^^^^^^^^
  File "/home/airflow/.local/lib/python3.12/site-packages/airflow/models/taskinstance.py", line 3006, in _run_raw_task
    return _run_raw_task(
           ^^^^^^^^^^^^^^
  File "/home/airflow/.local/lib/python3.12/site-packages/airflow/models/taskinstance.py", line 274, in _run_raw_task
    TaskInstance._execute_task_with_callbacks(
  File "/home/airflow/.local/lib/python3.12/site-packages/airflow/models/taskinstance.py", line 3161, in _execute_task_with_callbacks
    result = self._execute_task(context, task_orig)
             ^^^^^^^^^^^^^^^^^^^^^^^^^^^^^^^^^^^^^^
  File "/home/airflow/.local/lib/python3.12/site-packages/airflow/models/taskinstance.py", line 3185, in _execute_task
    return _execute_task(self, context, task_orig)
           ^^^^^^^^^^^^^^^^^^^^^^^^^^^^^^^^^^^^^^^
  File "/home/airflow/.local/lib/python3.12/site-packages/airflow/models/taskinstance.py", line 768, in _execute_task
    result = _execute_callable(context=context, **execute_callable_kwargs)
             ^^^^^^^^^^^^^^^^^^^^^^^^^^^^^^^^^^^^^^^^^^^^^^^^^^^^^^^^^^^^^
  File "/home/airflow/.local/lib/python3.12/site-packages/airflow/models/taskinstance.py", line 734, in _execute_callable
    return ExecutionCallableRunner(
           ^^^^^^^^^^^^^^^^^^^^^^^^
  File "/home/airflow/.local/lib/python3.12/site-packages/airflow/utils/operator_helpers.py", line 252, in run
    return self.func(*args, **kwargs)
           ^^^^^^^^^^^^^^^^^^^^^^^^^^
  File "/home/airflow/.local/lib/python3.12/site-packages/airflow/models/baseoperator.py", line 424, in wrapper
    return func(self, *args, **kwargs)
           ^^^^^^^^^^^^^^^^^^^^^^^^^^^
  File "/home/airflow/.local/lib/python3.12/site-packages/airflow/operators/python.py", line 238, in execute
    return_value = self.execute_callable()
                   ^^^^^^^^^^^^^^^^^^^^^^^
  File "/home/airflow/.local/lib/python3.12/site-packages/airflow/operators/python.py", line 256, in execute_callable
    return runner.run(*self.op_args, **self.op_kwargs)
           ^^^^^^^^^^^^^^^^^^^^^^^^^^^^^^^^^^^^^^^^^^^
  File "/home/airflow/.local/lib/python3.12/site-packages/airflow/utils/operator_helpers.py", line 252, in run
    return self.func(*args, **kwargs)
           ^^^^^^^^^^^^^^^^^^^^^^^^^^
  File "/opt/airflow/assign2/main4.py", line 113, in main4
    with open('/opt/airflow/dags/run/status', 'w') as f:
         ^^^^^^^^^^^^^^^^^^^^^^^^^^^^^^^^^^^^^^^^^
FileNotFoundError: [Errno 2] No such file or directory: '/opt/airflow/dags/run/status'
[2025-02-16T00:06:18.451+0000] {local_task_job_runner.py:266} INFO - Task exited with return code 1
[2025-02-16T00:06:18.492+0000] {taskinstance.py:3901} INFO - 0 downstream tasks scheduled from follow-on schedule check
[2025-02-16T00:06:18.499+0000] {local_task_job_runner.py:245} INFO - ::endgroup::
